Workbook
Name FP.DataSourceName: '[1]Front Page'!$H$15
Name FP.LastPrice: '[1]Front Page'!$H$20
Name FP.LastPriceDate: '[1]Front Page'!$F$20
Name FP.RealTimeToggle: '[1]Front Page'!$H$18
Name GD_Guidance_High: [2]Guidance!$J:$J
Name GD_Guidance_Low: [2]Guidance!$I:$I
Name GD_Guidance_Mid: [2]Guidance!$K:$K
Name GD_Item_FiscalPeriod: [2]Guidance!$F:$F
Name GD_Item_Name: [2]Guidance!$E:$E
Name GD_Update_Date: [2]Guidance!$S:$S
Name HP.MRFX: WSM!$B$1290
Name HP.ReportCurrency: WSM!$B$1289
Name HP.Ticker: WSM!$A$2
Name HP.TradeCurrency: WSM!$B$1287
Name HP.TradeCurrency.HardCoded: WSM!$B$1288
Name MO.ApplyTradeCurrencyScaling: WSM!$B$1286
Name MO.DataSourceIndex: WSM!$B$1297
Name MO.DataSourceName: WSM!$A$4
Name MO.LastPrice: WSM!$B$3
Name MO.LastPriceFormula: WSM!$B$1285
Name MO.LastPriceHardcoded: WSM!$B$1282
Name MO.MRFP: WSM!$B$1293
Name MO.MRFPColumnNumber: WSM!$B$1292
Name MO.MRFX.Hardcoded: WSM!$B$1291
Name MO.RealTime: WSM!$B$4
Name MO.RealTimeStockPriceToggle: WSM!$B$1284
Name MO.ReportCurrency: WSM!$B$1289
Name MO.ReportFX: WSM!$A$5
Name MO.Ticker.Bloomberg: WSM!$A$1189
Name MO.Ticker.CapIQ: WSM!$A$1190
Name MO.Ticker.FactSet: WSM!$A$1191
Name MO.Ticker.Thomson: WSM!$A$1192
Name MO.ValuationToggle: WSM!$B$924
Name MO_CFS_Buyback: WSM!$1045:$1045
Name MO_CFS_CFF: WSM!$1054:$1054
Name MO_CFS_CFI: WSM!$1039:$1039
Name MO_CFS_CFO: WSM!$1030:$1030
Name MO_CFS_CFO_BeforeWC: WSM!$1019:$1019
Name MO_CFSum_Acquisition: WSM!$881:$881
Name MO_CFSum_Capex: WSM!$879:$879
Name MO_CFSum_Divestiture: WSM!$882:$882
Name MO_CFSum_Dividend: WSM!$883:$883
Name MO_Common_ColumnHeader: WSM!$5:$5
Name MO_Common_FPDays: WSM!$3:$3
Name MO_Common_QEndDate: WSM!$4:$4
Name MO_IS_EBIT: WSM!$644:$644
Name MO_IS_FirstRow: WSM!$640:$640
Name MO_OS_EBIT: WSM!$352:$352
Name MO_OS_EBIT_Adj: WSM!$366:$366
Name MO_OS_EBT: WSM!$379:$379
Name MO_OS_EBT_Adj: WSM!$381:$381
Name MO_RIS_EBIT: WSM!$762:$762
Name MO_RIS_EBIT_Adj: WSM!$763:$763
Name MO_RIS_EBITDA_Adj: WSM!$769:$769
Name MO_RIS_EBT: WSM!$778:$778
Name MO_RIS_EBT_Adj: WSM!$779:$779
Name MO_RIS_EPS_WAD_Adj: WSM!$811:$811
Name MO_RIS_NI_NONGAAP_Diluted: WSM!$802:$802
Name MO_RIS_REV: WSM!$749:$749
Name MO_SCA_ShareCount_EoP_Diluted: WSM!$833:$833

Sheet P&L
B6: CONFIDENTIAL
B7: mock analysis
B9: Green = to fill out
B10: 1. Compute each fee as a % of STOWED product revenue.
B11: 2. Compute total fees and revenue per resort.
B12: 3. Compute FY1, 2, and 3 revenue using table in rows 29-32.
B13: 4. Compute COGS using a 60% margin.
B14: 5. Compute gross profit $ and %.
B15: 6. Add SG&A categories + estimates.
B16: 7. Compute net operating profit $ and %.
B18: Revenue Streams | C18: as % of STOWED product budget | D18: resort a | E18: resort b | F18: resort c | G18: resort d | H18: resort e | I18: resort f | J18: resort g | K18: resort h | L18: resort i | M18: TOTAL
B19: STOWED product | D19: 1000000 | E19: 2000000 | F19: 1000000 | G19: 3000000 | H19: 2000000 | I19: 3000000 | J19: 1000000 | K19: 2000000 | L19: 2000000 | M19: =SUM(D19:L19) -> 17000000
B20: Fees
B21: Design | C21: 0.03 | D21: =D$19*$C21 -> 30000 | E21: =E$19*$C21 -> 60000 | F21: =F$19*$C21 -> 30000 | G21: =G$19*$C21 -> 90000 | H21: =H$19*$C21 -> 60000 | I21: =I$19*$C21 -> 90000 | J21: =J$19*$C21 -> 30000 | K21: =K$19*$C21 -> 60000 | L21: =L$19*$C21 -> 60000 | M21: =SUM(D21:L21) -> 510000
B22: Product Development | C22: 0.06 | D22: =D$19*$C22 -> 60000 | E22: =E$19*$C22 -> 120000 | F22: =F$19*$C22 -> 60000 | G22: =G$19*$C22 -> 180000 | H22: =H$19*$C22 -> 120000 | I22: =I$19*$C22 -> 180000 | J22: =J$19*$C22 -> 60000 | K22: =K$19*$C22 -> 120000 | L22: =L$19*$C22 -> 120000 | M22: =SUM(D22:L22) -> 1020000
B23: Consulting | C23: 0.07 | D23: =D$19*$C23 -> 70000 | E23: =E$19*$C23 -> 140000 | F23: =F$19*$C23 -> 70000 | G23: =G$19*$C23 -> 210000 | H23: =H$19*$C23 -> 140000 | I23: =I$19*$C23 -> 210000 | J23: =J$19*$C23 -> 70000 | K23: =K$19*$C23 -> 140000 | L23: =L$19*$C23 -> 140000 | M23: =SUM(D23:L23) -> 1190000
B24: Logistics | C24: 0.02 | D24: =D$19*$C24 -> 20000 | E24: =E$19*$C24 -> 40000 | F24: =F$19*$C24 -> 20000 | G24: =G$19*$C24 -> 60000 | H24: =H$19*$C24 -> 40000 | I24: =I$19*$C24 -> 60000 | J24: =J$19*$C24 -> 20000 | K24: =K$19*$C24 -> 40000 | L24: =L$19*$C24 -> 40000 | M24: =SUM(D24:L24) -> 340000
B25: Total Fees | D25: =SUM(D21:D24) -> 180000 | E25: =SUM(E21:E24) -> 360000 | F25: =SUM(F21:F24) -> 180000 | G25: =SUM(G21:G24) -> 540000 | H25: =SUM(H21:H24) -> 360000 | I25: =SUM(I21:I24) -> 540000 | J25: =SUM(J21:J24) -> 180000 | K25: =SUM(K21:K24) -> 360000 | ... M25: =SUM(M21:M24) -> 3060000
B26: Total Revenue | D26: =D19+D25 -> 1180000 | E26: =E19+E25 -> 2360000 | F26: =F19+F25 -> 1180000 | G26: =G19+G25 -> 3540000 | H26: =H19+H25 -> 2360000 | I26: =I19+I25 -> 3540000 | J26: =J19+J25 -> 1180000 | K26: =K19+K25 -> 2360000 | ... M26: =M19+M25 -> 20060000
B29: % of resort revenue per year
B30: Yr1 | D30: 1 | E30: 0.75 | F30: 0.6 | G30: 0.8 | H30: 0 | I30: 0 | J30: 0.5 | K30: 0 | L30: 0
B31: Yr2 | D31: 0 | E31: 0 | F31: 0.3 | G31: 0.1 | H31: 0.3 | I31: 0 | J31: 0.25 | K31: 0.15 | L31: 1
B32: Yr3 | D32: =1-D31-D30 -> 0 | E32: =1-E31-E30 -> 0.25 | F32: =1-F31-F30 -> 0.1 | G32: 0.1 | H32: 0.7 | I32: 1 | J32: 0.25 | K32: 0.85 | L32: =1-L31-L30 -> 0
B37: P&L
B38: REVENUE | D38: FY1 | F38: FY2 | H38: FY3 | J38: Total
B39: STOWED product | D39: =SUMPRODUCT($D$19:$L$19,D30:L30) -> 6000000 | F39: =SUMPRODUCT($D$19:$L$19,D31:L31) -> 3750000 | H39: =SUMPRODUCT($D$19:$L$19,D32:L32) -> 7250000 | J39: =SUM(H39,F39,D39) -> 17000000
B40: Fees | D40: =SUMPRODUCT($D$25:$L$25,D30:L30) -> 1080000 | F40: =SUMPRODUCT($D$25:$L$25,F30:N30) -> 576000 | H40: =SUMPRODUCT($D$25:$L$25,H30:P30) -> 90000 | J40: =SUM(H40,F40,D40) -> 1746000
B41: Revenue | D41: =SUMPRODUCT($D$26:$L$26,D30:L30) -> 7080000 | F41: =SUMPRODUCT($D$26:$L$26,D31:L31) -> 4425000 | H41: =SUMPRODUCT($D$26:$L$26,D32:L32) -> 8555000 | J41: =SUM(H41,F41,D41) -> 20060000
B42: STOWED COGS (use 60% margin) | C42: 0.6 | D42: =-D41*$C$42 -> -4248000 | F42: =-F41*$C$42 -> -2655000 | H42: =-H41*$C$42 -> -5133000 | J42: =SUM(H42,F42,D42) -> -12036000
B43: Gross profit $ | D43: =SUM(D41:D42) -> 2832000 | F43: =SUM(F41:F42) -> 1770000 | H43: =SUM(H41:H42) -> 3422000 | J43: =SUM(J41:J42) -> 8024000
B44: Gross profit % | D44: =D43/D41 -> 0.4 | F44: =F43/F41 -> 0.4 | H44: =H43/H41 -> 0.4 | J44: =J43/J41 -> 0.4
B45: SG&A
B46: Selling
B47: General | D47: -200000 | F47: -200000 | H47: -200000 | J47: 0
B48: Administrative | D48: ='Team Structure'!M110*-1 -> -1087647.1 | F48: ='Team Structure'!N110*-1 -> -1070000 | H48: ='Team Structure'!O110*-1 -> -1168382.4 | J48: =SUM(D48:H48) -> -3326029.4
B49: Net Operating Profit $ | D49: =D43+SUM(D46:D48) -> 1544352.9 | F49: =F43+SUM(F46:F48) -> 500000 | H49: =H43+SUM(H46:H48) -> 2053617.6 | J49: =J43+SUM(J46:J48) -> 4697970.6
B50: Net Operating Profit % | D50: =D49/D41 -> 0.21812895 | F50: =F49/F41 -> 0.11299435 | H50: =H49/H41 -> 0.24004882 | J50: =J49/J41 -> 0.23419594
B53: General as a % of revenue | D53: =D47/D41*-1 -> 0.028248588 | F53: =F47/F41*-1 -> 0.04519774 | H53: =H47/H41*-1 -> 0.023378141
B54: Selling

Sheet Comps
C2: RH | D2: WSM | E2: Wayfair
B4: Gross Margin | C4: =RH!BI23 -> 0.45855438 | D4: =WSM!BI41 -> 0.42651147 | E4: =Wayfair!BI97 -> 0.30550696
B5: SG&A | C5: =RH!BI638 -> 0.32855418 | D5: =D4-D7 -> 0.26257681
B7: Operating margin | C7: =C4-C5 -> 0.1300002 | D7: =WSM!BI46 -> 0.16393466

Sheet Team Structure
C2: 1. Compute annual and total salaries per team (assume all W2 employees with full benefits).
C3: 2. Compute annual and total fees per team.
C4: 3. Compute ROI per team.
C5: 4. Provide a hypothesis for current allocation of team members and salaries vs. ROI.
C6: 5. Provide a suggestion for reallocation of team members and salaries vs. ROI.
C8: Employee | E8: Team | F8: Salary | G8: Assumed hours worked if completed within a year | H8: Salary per Hour | J8: Group | K8: Average Salary | L8: Total Hours to Complete Project | M8: Average Hour per year | N8: Total personel Required
C9: A | E9: Design | F9: 150000 | G9: =(40*49) -> 1960 | H9: =F9/G9 -> 76.530612 | J9: Design | K9: =AVERAGE(F9:F13) -> 110000 | L9: =SUMIF($E$9:$E$20,$J9,$G$9:$G$20) -> 9800 | M9: =L9/3 -> 3266.6667 | N9: =ROUND(M9/G9,0) -> 2
C10: B | E10: Design | F10: 125000 | G10: =(40*49) -> 1960 | H10: =F10/G10 -> 63.77551 | J10: Product Development | K10: =AVERAGE(F14:F15) -> 135000 | L10: =SUMIF($E$9:$E$20,$J10,$G$9:$G$20) -> 3920 | M10: =L10/3 -> 1306.6667 | N10: =M10/G14 -> 0.66666667
C11: C | E11: Design | F11: 110000 | G11: =(40*49) -> 1960 | H11: =F11/G11 -> 56.122449 | J11: Consulting | K11: =AVERAGE(F16:F19) -> 168750 | L11: =SUMIF($E$9:$E$20,$J11,$G$9:$G$20) -> 7840 | M11: =L11/3 -> 2613.3333 | N11: =M11/G16 -> 1.3333333
C12: D | E12: Design | F12: 90000 | G12: =(40*49) -> 1960 | H12: =F12/G12 -> 45.918367 | J12: Logistics | K12: =AVERAGE(F20) -> 125000 | L12: =SUMIF($E$9:$E$20,$J12,$G$9:$G$20) -> 1960 | M12: =L12/3 -> 653.33333 | N12: =M12/G20 -> 0.33333333
C13: E | E13: Design | F13: 75000 | G13: =(40*49) -> 1960 | H13: =F13/G13 -> 38.265306 | J13: Total | L13: =SUM(L9:L12) -> 23520 | M13: =L13/3 -> 7840 | N13: =M13/G13 -> 4
C14: F | E14: Product Development | F14: 150000 | G14: =(40*49) -> 1960 | H14: =F14/G14 -> 76.530612
C15: G | E15: Product Development | F15: 120000 | G15: =(40*49) -> 1960 | H15: =F15/G15 -> 61.22449
C16: H | E16: Consulting | F16: 200000 | G16: =(40*49) -> 1960 | H16: =F16/G16 -> 102.04082
C17: I | E17: Consulting | F17: 200000 | G17: =(40*49) -> 1960 | H17: =F17/G17 -> 102.04082
C18: J | E18: Consulting | F18: 150000 | G18: =(40*49) -> 1960 | H18: =F18/G18 -> 76.530612
C19: K | E19: Consulting | F19: 125000 | G19: =(40*49) -> 1960 | H19: =F19/G19 -> 63.77551
C20: L | E20: Logistics | F20: 125000 | G20: =(40*49) -> 1960 | H20: =F20/G20 -> 63.77551
A22: 1
F24: Annual Salary | H24: FY1 | I24: FY2 | J24: FY3 | K24: Total
C25: Design | F25: =SUMIFS($F$9:$F$20,$E$9:$E$20,$C25) -> 550000 | H25: =$F25 -> 550000 | I25: =$F25 -> 550000 | J25: =$F25 -> 550000 | K25: =SUM(H25:J25) -> 1650000
C26: Product Development | F26: =SUMIFS($F$9:$F$20,$E$9:$E$20,$C26) -> 270000 | H26: =$F26 -> 270000 | I26: =$F26 -> 270000 | J26: =$F26 -> 270000 | K26: =SUM(H26:J26) -> 810000
C27: Consulting | F27: =SUMIFS($F$9:$F$20,$E$9:$E$20,$C27) -> 675000 | H27: =$F27 -> 675000 | I27: =$F27 -> 675000 | J27: =$F27 -> 675000 | K27: =SUM(H27:J27) -> 2025000
C28: Logistics | F28: =SUMIFS($F$9:$F$20,$E$9:$E$20,$C28) -> 125000 | H28: =$F28 -> 125000 | I28: =$F28 -> 125000 | J28: =$F28 -> 125000 | K28: =SUM(H28:J28) -> 375000
C29: Total | H29: =SUM(H25:H28) -> 1620000 | I29: =SUM(I25:I28) -> 1620000 | J29: =SUM(J25:J28) -> 1620000 | K29: =SUM(H29:J29) -> 4860000
A31: 2
H33: =H39/$K$39 -> 0.35294118 | I33: =I39/$K$39 -> 0.22058824 | J33: =J39/$K$39 -> 0.42647059 | N33: Total Hours worked
C34: Fees Generated | H34: FY1 | I34: FY2 | J34: FY3 | K34: Total | L34: Avg Fee per Hour | N34: FY1 | O34: =I34 -> FY2 | P34: =J34 -> FY3 | Q34: Total
C35: Design | H35: =SUMPRODUCT('P&L'!$D21:$L21,'P&L'!$D$30:$L$30) -> 180000 | I35: =SUMPRODUCT('P&L'!$D21:$L21,'P&L'!$D$31:$L$31) -> 112500 | J35: =SUMPRODUCT('P&L'!$D21:$L21,'P&L'!$D$32:$L$32) -> 217500 | K35: =SUM(H35:J35) -> 510000 | L35: =K35/L9 -> 52.040816
C36: Product Development | H36: =SUMPRODUCT('P&L'!$D22:$L22,'P&L'!$D$30:$L$30) -> 360000 | I36: =SUMPRODUCT('P&L'!$D22:$L22,'P&L'!$D$31:$L$31) -> 225000 | J36: =SUMPRODUCT('P&L'!$D22:$L22,'P&L'!$D$32:$L$32) -> 435000 | K36: =SUM(H36:J36) -> 1020000 | L36: =K36/L10 -> 260.20408
C37: Consulting | H37: =SUMPRODUCT('P&L'!$D23:$L23,'P&L'!$D$30:$L$30) -> 420000 | I37: =SUMPRODUCT('P&L'!$D23:$L23,'P&L'!$D$31:$L$31) -> 262500 | J37: =SUMPRODUCT('P&L'!$D23:$L23,'P&L'!$D$32:$L$32) -> 507500 | K37: =SUM(H37:J37) -> 1190000 | L37: =K37/L11 -> 151.78571
C38: Logistics | H38: =SUMPRODUCT('P&L'!$D24:$L24,'P&L'!$D$30:$L$30) -> 120000 | I38: =SUMPRODUCT('P&L'!$D24:$L24,'P&L'!$D$31:$L$31) -> 75000 | J38: =SUMPRODUCT('P&L'!$D24:$L24,'P&L'!$D$32:$L$32) -> 145000 | K38: =SUM(H38:J38) -> 340000 | L38: =K38/L12 -> 173.46939
C39: Total | H39: =SUM(H35:H38) -> 1080000 | I39: =SUM(I35:I38) -> 675000 | J39: =SUM(J35:J38) -> 1305000 | K39: =SUM(K35:K38) -> 3060000
A41: 3 | C41: ROI
C43: ROI | H43: FY1 | I43: FY2 | J43: FY3 | K43: Total
C44: Design | H44: =H35/H25 -> 0.32727273 | I44: =I35/I25 -> 0.20454545 | J44: =J35/J25 -> 0.39545455 | K44: =K35/K25 -> 0.30909091
C45: Product Development | H45: =H36/H26 -> 1.3333333 | I45: =I36/I26 -> 0.83333333 | J45: =J36/J26 -> 1.6111111 | K45: =K36/K26 -> 1.2592593
C46: Consulting | H46: =H37/H27 -> 0.62222222 | I46: =I37/I27 -> 0.38888889 | J46: =J37/J27 -> 0.75185185 | K46: =K37/K27 -> 0.58765432
C47: Logistics | H47: =H38/H28 -> 0.96 | I47: =I38/I28 -> 0.6 | J47: =J38/J28 -> 1.16 | K47: =K38/K28 -> 0.90666667
C48: Total | H48: =H39/H29 -> 0.66666667 | I48: =I39/I29 -> 0.41666667 | J48: =J39/J29 -> 0.80555556 | K48: =K39/K29 -> 0.62962963
...

Sheet Questions
B2: Questions
B3: Are Fees paid on the same schedule as Revenue?
B4: Is COGS based on total revenue or just STOWED product?

Sheet Support>>>

Sheet RH
A1: RH
A2: RH US | C2: 39844 | AF2: Restated | AG2: Restated | AH2: Restated | AI2: Restated | AJ2: Restated | AZ2: Restated | BA2: Restated | BB2: Restated
A3: USD | B3: 334.75 | C3: 364 | D3: 364 | E3: 364 | F3: 371 | G3: 91 | H3: 91 | I3: 91 | J3: 91 | K3: 364 | L3: 91 | M3: 91 | N3: 91 | O3: 91 | P3: 364 | Q3: 91 | R3: 91 | S3: 91 | T3: 91 | U3: 364 | V3: 91 | W3: 91 | X3: 91 | Y3: 91 | Z3: 364 | AA3: 91 | AB3: 91 | AC3: 91 | AD3: 98 | AE3: 371 | AF3: 91 | AG3: 91 | AH3: 91 | AI3: 91 | AJ3: 364 | AK3: 91 | AL3: 91 | AM3: 91 | AN3: 91 | AO3: 364 | AP3: 91 | AQ3: 91 | AR3: 91 | AS3: 91 | AT3: 364 | AU3: 91 | AV3: 91 | AW3: 91 | AX3: 91 | AY3: 364 | AZ3: 91 | BA3: 91 | BB3: 91 | BC3: 91 | BD3: 364 | BE3: 91 | BF3: 91 | BG3: 91 | BH3: 98 | BI3: 371 | BJ3: 91 | BK3: 91 | BL3: 91 | BM3: 91 | BN3: 364 | BO3: 91 | BP3: 91 | BQ3: 91 | BR3: 91 | BS3: 364 | BT3: 364 | BU3: 364 | BV3: 371
A4: Bloomberg | B4: OFF | C4: 40208 | D4: 40572 | E4: 40936 | F4: 41307 | G4: 41398 | H4: 41489 | I4: 41580 | J4: 41671 | K4: 41671 | L4: 41762 | M4: 41853 | N4: 41944 | O4: 42035 | P4: 42035 | Q4: 42126 | R4: 42217 | S4: 42308 | T4: 42399 | U4: 42399 | V4: 42490 | W4: 42581 | X4: 42672 | Y4: 42763 | Z4: 42763 | AA4: 42854 | AB4: 42945 | AC4: 43036 | AD4: 43134 | AE4: 43134 | AF4: 43225 | AG4: 43316 | AH4: 43407 | AI4: 43498 | AJ4: 43498 | AK4: 43589 | AL4: 43680 | AM4: 43771 | AN4: 43862 | AO4: 43862 | AP4: 43953 | AQ4: 44044 | AR4: 44135 | AS4: 44226 | AT4: 44226 | AU4: 44317 | AV4: 44408 | AW4: 44499 | AX4: 44590 | AY4: 44590 | AZ4: 44681 | BA4: 44772 | BB4: 44863 | BC4: 44954 | BD4: 44954 | BE4: 45045 | BF4: 45136 | BG4: 45227 | BH4: 45325 | BI4: 45325 | BJ4: 45416 | BK4: 45507 | BL4: 45598 | BM4: 45689 | BN4: 45689 | BO4: 45780 | BP4: 45871 | BQ4: 45962 | BR4: 46053 | BS4: 46053 | BT4: 46417 | BU4: 46781 | BV4: 47152
A5: USD | C5: FY2009 | D5: FY2010 | E5: FY2011 | F5: FY2012 | G5: Q1-2013 | H5: Q2-2013 | I5: Q3-2013 | J5: Q4-2013 | K5: FY2013 | L5: Q1-2014 | M5: Q2-2014 | N5: Q3-2014 | O5: Q4-2014 | P5: FY2014 | Q5: Q1-2015 | R5: Q2-2015 | S5: Q3-2015 | T5: Q4-2015 | U5: FY2015 | V5: Q1-2016 | W5: Q2-2016 | X5: Q3-2016 | Y5: Q4-2016 | Z5: FY2016 | AA5: Q1-2017 | AB5: Q2-2017 | AC5: Q3-2017 | AD5: Q4-2017 | AE5: FY2017 | AF5: Q1-2018 | AG5: Q2-2018 | AH5: Q3-2018 | AI5: Q4-2018 | AJ5: FY2018 | AK5: Q1-2019 | AL5: Q2-2019 | AM5: Q3-2019 | AN5: Q4-2019 | AO5: FY2019 | AP5: Q1-2020 | AQ5: Q2-2020 | AR5: Q3-2020 | AS5: Q4-2020 | AT5: FY2020 | AU5: Q1-2021 | AV5: Q2-2021 | AW5: Q3-2021 | AX5: Q4-2021 | AY5: FY2021 | AZ5: Q1-2022 | BA5: Q2-2022 | BB5: Q3-2022 | BC5: Q4-2022 | BD5: FY2022 | BE5: Q1-2023 | BF5: Q2-2023 | BG5: Q3-2023 | BH5: Q4-2023 | BI5: FY2023 | BJ5: Q1-2024 | BK5: Q2-2024 | BL5: Q3-2024 | BM5: Q4-2024 | BN5: FY2024 | BO5: Q1-2025 | BP5: Q2-2025 | BQ5: Q3-2025 | BR5: Q4-2025 | BS5: FY2025 | BT5: FY2026 | BU5: FY2027 | BV5: FY2028
A6: Consolidated Summary
A7: Total Retail Locations - EoP, # of stores | C7: 95 | D7: 91 | E7: 74 | F7: 71 | G7: 70 | H7: 70 | I7: 70 | J7: 70 | K7: 70 | L7: 69 | M7: 68 | N7: 68 | O7: 67 | P7: 67 | Q7: 67 | R7: 67 | S7: 68 | T7: 69 | U7: 69 | V7: 69 | W7: 84 | X7: 85 | Y7: 85 | Z7: 85 | AA7: 85 | AB7: 85 | AC7: 84 | AD7: 83 | AE7: 83 | AF7: 84 | AG7: 85 | AH7: 86 | AI7: 86 | AJ7: 86 | AK7: 85 | AL7: 85 | AM7: 85 | AN7: 83 | AO7: 83 | AP7: 84 | AQ7: 83 | AR7: 82 | AS7: 82 | AT7: 82 | AU7: 82 | AV7: 80 | AW7: 80 | AX7: 81 | AY7: 81 | AZ7: 81 | BA7: 81 | BB7: 81 | BC7: 81 | BD7: 81 | BE7: 81 | BF7: 82 | BG7: 82 | BH7: 84 | BI7: 84 | BJ7: 86 | BK7: 88 | BL7: 90 | BM7: 91 | BN7: 91 | BO7: 92 | BP7: 93 | BQ7: 94 | BR7: 94 | BS7: 94 | BT7: 95 | BU7: 95 | BV7: 95
A8: Q/Q Total retail locations - EoP growth, % | G8: -0.014084507 | H8: 0 | I8: 0 | J8: 0 | L8: -0.014285714 | M8: -0.014492754 | N8: 0 | O8: -0.014705882 | Q8: 0 | R8: 0 | S8: 0.014925373 | T8: 0.014705882 | V8: 0 | W8: 0.2173913 | X8: 0.011904762 | Y8: 0 | AA8: 0 | AB8: 0 | AC8: -0.011764706 | AD8: -0.011904762 | AF8: 0.012048193 | AG8: 0.011904762 | AH8: 0.011764706 | AI8: 0 | AK8: -0.011627907 | AL8: 0 | AM8: 0 | AN8: -0.023529412 | AP8: 0.012048193 | AQ8: -0.011904762 | AR8: -0.012048193 | AS8: 0 | AU8: 0 | AV8: -0.024390244 | AW8: 0 | AX8: 0.0125 | AZ8: 0 | BA8: 0 | BB8: 0 | BC8: 0 | BE8: 0 | BF8: 0.012345679 | BG8: 0 | BH8: 0.024390244 | BJ8: 0.023809524 | BK8: 0.023255814 | BL8: 0.022727273 | BM8: 0.011111111 | BO8: 0.010989011 | BP8: 0.010869565 | BQ8: 0.010752688 | BR8: 0
A9: Y/Y Total retail locations - EoP growth, % | D9: -0.042105263 | E9: -0.18681319 | F9: -0.040540541 | K9: -0.014084507 | L9: -0.014285714 | M9: -0.028571429 | N9: -0.028571429 | O9: -0.042857143 | P9: -0.042857143 | Q9: -0.028985507 | R9: -0.014705882 | S9: 0 | T9: 0.029850746 | U9: 0.029850746 | V9: 0.029850746 | W9: 0.25373134 | X9: 0.25 | Y9: 0.23188406 | Z9: 0.23188406 | AA9: 0.23188406 | AB9: 0.011904762 | AC9: -0.011764706 | AD9: -0.023529412 | AE9: -0.023529412 | AF9: -0.011764706 | AG9: 0 | AH9: 0.023809524 | AI9: 0.036144578 | AJ9: 0.036144578 | AK9: 0.011904762 | AL9: 0 | AM9: -0.011627907 | AN9: -0.034883721 | AO9: -0.034883721 | AP9: -0.011764706 | AQ9: -0.023529412 | AR9: -0.035294118 | AS9: -0.012048193 | AT9: -0.012048193 | AU9: -0.023809524 | AV9: -0.036144578 | AW9: -0.024390244 | AX9: -0.012195122 | AY9: -0.012195122 | AZ9: -0.012195122 | BA9: 0.0125 | BB9: 0.0125 | BC9: 0 | BD9: 0 | BE9: 0 | BF9: 0.012345679 | BG9: 0.012345679 | BH9: 0.037037037 | BI9: 0.037037037 | BJ9: 0.061728395 | BK9: 0.073170732 | BL9: 0.097560976 | BM9: 0.083333333 | BN9: 0.083333333 | BO9: 0.069767442 | BP9: 0.056818182 | BQ9: 0.044444444 | BR9: 0.032967033 | BS9: 0.032967033 | BT9: 0.010638298 | BU9: 0 | BV9: 0
A11: RH Segment revenue, mm | C11: 625.685 | D11: 772.752 | E11: 958.084 | F11: 1193.046 | G11: 301.337 | H11: 382.098 | I11: 395.832 | J11: 471.694 | K11: 1550.961 | L11: 366.254 | M11: 433.766 | N11: 484.675 | O11: 582.727 | P11: 1867.422 | Q11: 422.445 | R11: 506.942 | S11: 532.411 | T11: 647.208 | U11: 2109.006 | V11: 455.456 | W11: 522.618 | X11: 521.027 | Y11: 560.943 | Z11: 2060.044 | AA11: 533.528 | AB11: 583.793 | AC11: 563.174 | AD11: 638.837 | AE11: 2319.332 | AF11: 526.007 | AG11: 607.604 | AH11: 604.322 | AI11: 637.539 | AJ11: 2375.472 | AK11: 563.706 | AL11: 672.328 | AM11: 645.378 | AN11: 632.884 | AO11: 2514.296 | AP11: 454.957 | AQ11: 681.387 | AR11: 812.782 | AS11: 780.296 | AT11: 2729.422 | AU11: 819.823 | AV11: 947.618 | AW11: 964.859 | AX11: 861.542 | AY11: 3593.842 | AZ11: 908.948 | BA11: 940.182 | BB11: 821.26 | BC11: 728.248 | BD11: 3398.638 | BE11: 690.516 | BF11: 753.55 | BG11: 705.061 | BH11: 686.49 | BI11: 2835.617 | BJ11: 676.85902 | BK11: 795.63632 | BL11: 809.15842 | BM11: 765.7331 | BN11: 3047.3869 | BO11: 805.83872 | BP11: 921.16825 | BQ11: 931.43026 | BR11: 842.84749 | BS11: 3501.2847 | BT11: 3708.4598 | BU11: 3827.795 | BV11: 3907.1631
A12: Y/Y RH core demand growth, % | AP12: -0.11 | AQ12: 0.24 | AR12: 0.42 | AS12: 0.36 | AU12: 1.09
A13: Y/Y RH Segment revenue growth, % | D13: 0.23504959 | E13: 0.23983374 | F13: 0.24524154 | K13: 0.30000101 | L13: 0.2154299 | M13: 0.13522185 | N13: 0.22444623 | O13: 0.23539201 | P13: 0.20404188 | Q13: 0.15342085 | R13: 0.16869925 | S13: 0.098490741 | T13: 0.11065387 | U13: 0.12936765 | V13: 0.078142717 | W13: 0.03092267 | X13: -0.021381977 | Y13: -0.13328791 | Z13: -0.023215676 | AA13: 0.17141502 | AB13: 0.1170549 | AC13: 0.080892161 | AD13: 0.13886259 | AE13: 0.12586527 | AF13: -0.01409673 | AG13: 0.040786717 | AH13: 0.073064453 | AI13: -0.0020318172 | AJ13: 0.024205245 | AK13: 0.071670149 | AL13: 0.10652333 | AM13: 0.067937292 | AN13: -0.0073015141 | AO13: 0.058440596 | AP13: -0.19291794 | AQ13: 0.013474078 | AR13: 0.25938907 | AS13: 0.23292104 | AT13: 0.085561127 | AU13: 0.80197909 | AV13: 0.39071922 | AW13: 0.18710675 | AX13: 0.10412203 | AY13: 0.31670442 | AZ13: 0.10871249 | BA13: -0.0078470439 | BB13: -0.148829 | BC13: -0.15471561 | BD13: -0.054316244 | BE13: -0.24031298 | BF13: -0.19850625 | BG13: -0.14148869 | BH13: -0.057340357 | BI13: -0.16566077 | BJ13: -0.019777931 | BK13: 0.055850731 | BL13: 0.14764314 | BM13: 0.11543227 | BN13: 0.07468211 | BO13: 0.19055622 | BP13: 0.15777551 | BQ13: 0.1511099 | BR13: 0.10070661 | BS13: 0.14894658 | BT13: 0.059171164 | BU13: 0.032179171 | BV13: 0.020734696
A14: Waterworks revenue, mm | W14: 20.763 | X14: 28.301 | Y14: 25.763 | Z14: 74.827 | AA14: 28.552 | AB14: 31.533 | AC14: 29.299 | AD14: 31.458 | AE14: 120.842 | AF14: 31.399 | AG14: 33.194 | AH14: 32.236 | AI14: 33.352 | AJ14: 130.181 | AK14: 34.715 | AL14: 34.186 | AM14: 32.148 | AN14: 32.092 | AO14: 133.141 | AP14: 27.938 | AQ14: 27.895 | AR14: 31.231 | AS14: 32.14 | AT14: 119.204 | AU14: 40.969 | AV14: 41.241 | AW14: 41.569 | AX14: 41.199 | AY14: 164.978 | AZ14: 48.344 | BA14: 51.438 | BB14: 47.806 | BC14: 44.251 | BD14: 191.839 | BE14: 48.646 | BF14: 46.929 | BG14: 46.164 | BH14: 51.77 | BI14: 193.509 | BJ14: 47.447647 | BK14: 48.233855 | BL14: 48.900061 | BM14: 51.41254 | BN14: 195.9941 | BO14: 48.871077 | BP14: 49.680871 | BQ14: 51.345065 | BR14: 53.983167 | BS14: 203.88018 | BT14: 209.99658 | BU14: 216.29648 | BV14: 222.78538
A15: Y/Y Waterworks revenue growth, % | AB15: 0.51871117 | AC15: 0.035263772 | AD15: 0.22105345 | AE15: NMF | AF15: 0.099712805 | AG15: 0.052674975 | AH15: 0.10024233 | AI15: 0.06020726 | AJ15: 0.077282733 | AK15: 0.10560846 | AL15: 0.029884919 | AM15: -0.0027298672 | AN15: -0.037778844 | AO15: 0.022737573 | AP15: -0.19521821 | AQ15: -0.1840227 | AR15: -0.028524325 | AS15: 0.0014956999 | AT15: -0.1046785 | AU15: 0.46642566 | AV15: 0.478437 | AW15: 0.33101726 | AX15: 0.28186061 | AY15: 0.38399718 | AZ15: 0.18001416 | BA15: 0.24725395 | BB15: 0.15003969 | BC15: 0.074079468 | BD15: 0.16281565 | BE15: 0.0062468972 | BF15: -0.087658929 | BG15: -0.034347153 | BH15: 0.16991706 | BI15: 0.0087052164 | BJ15: -0.024634146 | BK15: 0.027804878 | BL15: 0.059268293 | BM15: -0.0069047619 | BN15: 0.012842319 | BO15: 0.03 | BP15: 0.03 | BQ15: 0.05 | BR15: 0.05 | BS15: 0.040236288 | BT15: 0.03 | BU15: 0.03 | BV15: 0.03
A16: Total Revenue, mm | C16: 625.685 | D16: 772.752 | E16: 958.084 | F16: 1193.046 | G16: 301.337 | H16: 382.098 | I16: 395.832 | J16: 471.694 | K16: 1550.961 | L16: 366.254 | M16: 433.766 | N16: 484.675 | O16: 582.727 | P16: 1867.422 | Q16: 422.445 | R16: 506.942 | S16: 532.411 | T16: 647.208 | U16: 2109.006 | V16: 455.456 | W16: 543.381 | X16: 549.328 | Y16: 586.706 | Z16: 2134.871 | AA16: 562.08 | AB16: 615.326 | AC16: 592.473 | AD16: 670.295 | AE16: 2440.174 | AF16: 557.406 | AG16: 640.798 | AH16: 636.558 | AI16: 670.891 | AJ16: 2505.653 | AK16: 598.421 | AL16: 706.514 | AM16: 677.526 | AN16: 664.976 | AO16: 2647.437 | AP16: 482.895 | AQ16: 709.282 | AR16: 844.013 | AS16: 812.436 | AT16: 2848.626 | AU16: 860.792 | AV16: 988.859 | AW16: 1006.428 | AX16: 902.741 | AY16: 3758.82 | AZ16: 957.292 | BA16: 991.62 | BB16: 869.066 | BC16: 772.499 | BD16: 3590.477 | BE16: 739.162 | BF16: 800.479 | BG16: 751.225 | BH16: 738.26 | BI16: 3029.126 | BJ16: 724.30667 | BK16: 843.87017 | BL16: 858.05848 | BM16: 817.14564 | BN16: 3243.381 | BO16: 854.70979 | BP16: 970.84912 | BQ16: 982.77533 | BR16: 896.83066 | BS16: 3705.1649 | BT16: 3918.4564 | BU16: 4044.0915 | BV16: 4129.9485
A17: Consensus Estimates - Net Revenue | BJ17: N/A | BK17: N/A | BL17: N/A | BM17: N/A | BN17: N/A | BO17: N/A | BP17: N/A | BQ17: N/A | BR17: N/A | BS17: N/A | BT17: N/A | BU17: N/A | BV17: N/A
A18: Y/Y Total company demand growth, % | AP18: -0.17 | AQ18: 0.16 | AR18: 0.33 | AS18: 0.29 | AU18: 1.01
A19: Y/Y Total revenue growth, % | D19: 0.23504959 | E19: 0.23983374 | F19: 0.24524154 | K19: 0.30000101 | L19: 0.2154299 | M19: 0.13522185 | N19: 0.22444623 | O19: 0.23539201 | P19: 0.20404188 | Q19: 0.15342085 | R19: 0.16869925 | S19: 0.098490741 | T19: 0.11065387 | U19: 0.12936765 | V19: 0.078142717 | W19: 0.071880018 | X19: 0.031774325 | Y19: -0.093481539 | Z19: 0.012264071 | AA19: 0.23410384 | AB19: 0.13240249 | AC19: 0.078541418 | AD19: 0.1424717 | AE19: 0.1430077 | AF19: -0.0083155423 | AG19: 0.041395943 | AH19: 0.074408454 | AI19: 0.00088916074 | AJ19: 0.026833742 | AK19: 0.073581913 | AL19: 0.10255338 | AM19: 0.064358629 | AN19: -0.0088166334 | AO19: 0.056585649 | AP19: -0.19305138 | AQ19: 0.0039178275 | AR19: 0.24572784 | AS19: 0.22175236 | AT19: 0.075993876 | AU19: 0.78256557 | AV19: 0.39416903 | AW19: 0.19243187 | AX19: 0.11115337 | AY19: 0.31952036 | AZ19: 0.11210606 | BA19: 0.0027921069 | BB19: -0.13648468 | BC19: -0.14427394 | BD19: -0.04478613 | BE19: -0.22786151 | BF19: -0.1927563 | BG19: -0.135595 | BH19: -0.044322387 | BI19: -0.15634441 | BJ19: -0.02009753 | BK19: 0.054206511 | BL19: 0.14221236 | BM19: 0.10685347 | BN19: 0.070731612 | BO19: 0.18003855 | BP19: 0.15047213 | BQ19: 0.14534773 | BR19: 0.097516295 | BS19: 0.14237733 | BT19: 0.057565993 | BU19: 0.032062385 | BV19: 0.021230247
A21: Adjusted Gross Profit, mm | C21: 200.276 | D21: 271.62 | E21: 356.349 | F21: 439.699 | G21: 101.877 | H21: 139.226 | I21: 140.8 | J21: 174.977 | K21: 556.88 | L21: 124.349 | M21: 167.909 | N21: 180.373 | O21: 218.143 | P21: 690.774 | Q21: 144.797 | R21: 199.107 | S21: 195.551 | T21: 230.451 | U21: 769.906 | V21: 135.204 | W21: 183.24 | X21: 177.605 | Y21: 204.463 | Z21: 700.512 | AA21: 171.636 | AB21: 210.869 | AC21: 218.622 | AD21: 257.524 | AE21: 858.651 | AF21: 209.269 | AG21: 267.125 | AH21: 255.185 | AI21: 260.257 | AJ21: 991.836 | AK21: 234.159 | AL21: 296.554 | AM21: 282.371 | AN21: 283.073 | AO21: 1096.157 | AP21: 202.004 | AQ21: 337.199 | AR21: 409.111 | AS21: 385.494 | AT21: 1333.808 | AU21: 406.977 | AV21: 487.676 | AW21: 505.254 | AX21: 454.304 | AY21: 1854.211 | AZ21: 498.583 | BA21: 523.218 | BB21: 431.704 | BC21: 369.406 | BD21: 1822.911 | BE21: 347.545 | BF21: 380.073 | BG21: 340.45 | BH21: 320.951 | BI21: 1389.019 | BJ21: 301.52462 | BK21: 384.71654 | BL21: 393.57637 | BM21: 366.25384 | BN21: 1446.0714 | BO21: 367.21034 | BP21: 446.69644 | BQ21: 453.68544 | BR21: 406.05243 | BS21: 1673.6447 | BT21: 1780.7683 | BU21: 1849.5216 | BV21: 1900.912
A22: Consensus Estimates - Adjusted Gross Profit | BJ22: N/A | BK22: N/A | BL22: N/A | BM22: N/A | BN22: N/A | BO22: N/A | BP22: N/A | BQ22: N/A | BR22: N/A | BS22: N/A | BT22: N/A | BU22: N/A | BV22: N/A
A23: Adjusted gross margin, % | C23: 0.32009078 | D23: 0.35149699 | E23: 0.3719392 | F23: 0.36855159 | G23: 0.33808328 | H23: 0.36437249 | I23: 0.35570646 | J23: 0.37095447 | K23: 0.35905481 | L23: 0.33951575 | M23: 0.38709581 | N23: 0.37215247 | O23: 0.37434854 | P23: 0.36990782 | Q23: 0.34275941 | R23: 0.39276091 | S23: 0.36729331 | T23: 0.35606946 | U23: 0.36505633 | V23: 0.29685414 | W23: 0.33722195 | X23: 0.32331321 | Y23: 0.34646114 | Z23: 0.32760046 | AA23: 0.30535867 | AB23: 0.34058426 | AC23: 0.36899909 | AD23: 0.38454268 | AE23: 0.3514192 | AF23: 0.37543371 | AG23: 0.41566107 | AH23: 0.39965952 | AI23: 0.38738924 | AJ23: 0.39509303 | AK23: 0.39102489 | AL23: 0.41974257 | AM23: 0.41726292 | AN23: 0.42568905 | AO23: 0.41410576 | AP23: 0.41831868 | AQ23: 0.47513696 | AR23: 0.48427309 | AS23: 0.47438292 | AT23: 0.46800297 | AU23: 0.47279366 | AV23: 0.49317041 | AW23: 0.50202697 | AX23: 0.5039194 | AY23: 0.49345357 | AZ23: 0.52082646 | BA23: 0.52763962 | BB23: 0.49674478 | BC23: 0.47819609 | BD23: 0.50770719 | BE23: 0.47018786 | BF23: 0.47480696 | BG23: 0.45319312 | BH23: 0.43473979 | BI23: 0.45855438 | BJ23: 0.41629414 | BK23: 0.45589541 | BL23: 0.45868245 | BM23: 0.44821122 | BN23: 0.44585307 | BO23: 0.4296316 | BP23: 0.46010903 | BQ23: 0.46163699 | BR23: 0.45276377 | BS23: 0.45170585 | BT23: 0.45445658 | BU23: 0.45733922 | BV23: 0.46027499
A24: Consensus Estimates - Adjusted Gross Margin, % | BJ24: N/A | BK24: N/A | BL24: N/A | BM24: N/A | BN24: N/A | BO24: N/A | BP24: N/A | BQ24: N/A | BR24: N/A | BS24: N/A | BT24: N/A | BU24: N/A | BV24: N/A
A25: Y/Y Adjusted gross margin improvement, bps | D25: 314.06207 | E25: 204.42216 | F25: -33.876139 | K25: -94.967844 | L25: 14.324704 | M25: 227.23317 | N25: 164.46012 | O25: 33.940624 | P25: 108.53014 | Q25: 32.436666 | R25: 56.651001 | S25: -48.591604 | T25: -182.79082 | U25: -48.514848 | V25: -459.05271 | W25: -555.38958 | X25: -439.80101 | Y25: -96.083193 | Z25: -374.55872 | AA25: 85.04526 | AB25: 33.623137 | AC25: 456.85882 | AD25: 380.8154 | AE25: 238.18739 | AF25: 700.75038 | AG25: 750.76803 | AH25: 306.60424 | AI25: 28.465622 | AJ25: 436.73824 | AK25: 155.91186 | AL25: 40.815006 | AM25: 176.03406 | AN25: 382.99809 | AO25: 190.12736 | AP25: 272.9379 | AQ25: 553.94395 | AR25: 670.10166 | AS25: 486.93876 | AT25: 538.9721 | AU25: 544.74978 | AV25: 180.3345 | AW25: 177.53882 | AX25: 295.36477 | AY25: 254.50598 | AZ25: 480.32797 | BA25: 344.69208 | BB25: -52.821895 | BC25: -257.23312 | BD25: 142.53624 | BE25: -506.38595 | BF25: -528.32661 | BG25: -435.51663 | BH25: -434.56295 | BI25: -491.52812 | BJ25: -538.93722 | BK25: -189.11545 | BL25: 54.893337 | BM25: 134.71424 | BN25: -127.01307 | BO25: 133.37464 | BP25: 42.13613 | BQ25: 29.545385 | BR25: 45.52548 | BS25: 58.527738 | BT25: 27.507337 | BU25: 28.826362 | BV25: 29.357739
A27: Adjusted Operating Income, mm | C27: -27.564 | D27: 8.192 | E27: 49.219 | F27: 68.674 | G27: 4.601 | H27: 34.18 | I27: 23.86 | J27: 58.26 | K27: 120.901 | L27: 13.978 | M27: 48.935 | N27: 36.688 | O27: 73.825 | P27: 173.426 | Q27: 18.597 | R27: 61.897 | S27: 49.952 | T27: 74.161 | U27: 204.607 | V27: 0.71 | W27: 33.175 | X27: 18.146 | Y27: 50.883 | Z27: 102.914 | AA27: 8.276 | AB27: 39.908 | AC27: 48.005 | AD27: 75.109 | AE27: 171.298 | AF27: 49.158 | AG27: 75.466 | AH27: 61.075 | AI27: 101.485 | AJ27: 287.184 | AK27: 70.494 | AL27: 105.013 | AM27: 87.761 | AN27: 115.827 | AO27: 379.095 | AP27: 48.067 | AQ27: 154.923 | AR27: 225.311 | AS27: 192.241 | AT27: 620.542 | AU27: 194.252 | AV27: 262.655 | AW27: 278.71 | AX27: 227.011 | AY27: 962.628 | AZ27: 236.53 | BA27: 244.734 | BB27: 180.349 | BC27: 128.213 | BD27: 789.826 | BE27: 110.392 | BF27: 161.364 | BG27: 55.163 | BH27: 66.868 | BI27: 393.787 | BJ27: 50.573551 | BK27: 149.10355 | BL27: 124.48482 | BM27: 109.02981 | BN27: 433.19173 | BO27: 99.686446 | BP27: 184.59997 | BQ27: 148.30292 | BR27: 140.63884 | BS27: 573.22818 | BT27: 654.25112 | BU27: 724.58128 | BV27: 790.17582
A28: Consensus Estimates - Adjusted EBIT | BJ28: N/A | BK28: N/A | BL28: N/A | BM28: N/A | BN28: N/A | BO28: N/A | BP28: N/A | BQ28: N/A | BR28: N/A | BS28: N/A | BT28: N/A | BU28: N/A | BV28: N/A
A29: Adjusted operating margin, % | C29: -0.044054117 | D29: 0.010601073 | E29: 0.051372322 | F29: 0.057561905 | G29: 0.01526862 | H29: 0.089453491 | I29: 0.060278098 | J29: 0.12351228 | K29: 0.077952315 | L29: 0.038164771 | M29: 0.11281428 | N29: 0.075696085 | O29: 0.12668883 | P29: 0.092869207 | Q29: 0.044022299 | R29: 0.12209878 | S29: 0.093822254 | T29: 0.11458604 | U29: 0.097015845 | V29: 0.0015588773 | W29: 0.061052926 | X29: 0.033033088 | Y29: 0.086220891 | Z29: 0.048128617 | AA29: 0.014723883 | AB29: 0.064457254 | AC29: 0.081024789 | AD29: 0.11215505 | AE29: 0.070106954 | AF29: 0.088190655 | AG29: 0.11742921 | AH29: 0.095652977 | AI29: 0.15105913 | AJ29: 0.11439834 | AK29: 0.11771877 | AL29: 0.14863541 | AM29: 0.12968545 | AN29: 0.17418223 | AO29: 0.14321436 | AP29: 0.099539237 | AQ29: 0.21829734 | AR29: 0.26670526 | AS29: 0.23656879 | AT29: 0.21773411 | AU29: 0.2256666 | AV29: 0.26561421 | AW29: 0.27692989 | AX29: 0.2518033 | AY29: 0.25618024 | AZ29: 0.24708239 | BA29: 0.2468022 | BB29: 0.20752049 | BC29: 0.16597174 | BD29: 0.21997801 | BE29: 0.1493475 | BF29: 0.2015843 | BG29: 0.07343073 | BH29: 0.090575136 | BI29: 0.1300002 | BJ29: 0.069823395 | BK29: 0.17669015 | BL29: 0.14507731 | BM29: 0.13342764 | BN29: 0.13356178 | BO29: 0.11663192 | BP29: 0.1901428 | BQ29: 0.15090216 | BR29: 0.15681761 | BS29: 0.15471057 | BT29: 0.16696654 | BU29: 0.17917035 | BV29: 0.19132825
A30: Consensus Estimates - Adjusted EBIT Margin, % | BJ30: 0 | BK30: 0 | BL30: 0 | BM30: 0 | BN30: 0 | BO30: 0 | BP30: 0 | BQ30: 0 | BR30: 0 | BS30: 0 | BT30: 0 | BU30: 0 | BV30: 0
A31: Y/Y Adjusted operating margin improvement, bps | D31: 546.55189 | E31: 407.7125 | F31: 61.895823 | K31: 203.9041 | L31: 228.96151 | M31: 233.60791 | N31: 154.17987 | O31: 31.765498 | P31: 149.16892 | Q31: 58.575279 | R31: 92.844982 | S31: 181.26169 | T31: -121.0279 | U31: 41.466385 | V31: -424.63422 | W31: -610.45854 | X31: -607.89166 | Y31: -283.65147 | Z31: -488.87228 | AA31: 131.65005 | AB31: 34.043283 | AC31: 479.91702 | AD31: 259.34154 | AE31: 219.78337 | AF31: 734.66772 | AG31: 529.71957 | AH31: 146.28188 | AI31: 389.04088 | AJ31: 442.91389 | AK31: 295.28112 | AL31: 312.06202 | AM31: 340.32477 | AN31: 231.23093 | AO31: 288.16017 | AP31: -181.79529 | AQ31: 696.61924 | AR31: 1370.198 | AS31: 623.8656 | AT31: 745.19751 | AU31: 1261.2736 | AV31: 473.16872 | AW31: 102.24639 | AX31: 152.34515 | AY31: 384.4613 | AZ31: 214.158 | BA31: -188.12005 | BB31: -694.09407 | BC31: -858.31565 | BD31: -362.02228 | BE31: -977.34891 | BF31: -452.17901 | BG31: -1340.8976 | BH31: -753.966 | BI31: -899.77809 | BJ31: -795.2411 | BK31: -248.94148 | BL31: 716.46581 | BM31: 428.52503 | BN31: 35.615742 | BO31: 468.08527 | BP31: 134.52649 | BQ31: 58.248505 | BR31: 233.89975 | BS31: 211.48794 | BT31: 122.55972 | BU31: 122.03806 | BV31: 121.57899
A33: Adjusted Diluted EPS, $/share | F33: 1.0163528 | G33: 0.055335274 | H33: 0.48635386 | I33: 0.31707629 | J33: 0.8276917 | K33: 1.709717 | L33: 0.17537139 | M33: 0.67128539 | N33: 0.49010902 | O33: 1.017222 | P33: 2.3595994 | Q33: 0.2345583 | R33: 0.85271463 | S33: 0.65394031 | T33: 0.97506055 | U33: 2.7160754 | V33: -0.050901643 | W33: 0.4387012 | X33: 0.19593686 | Y33: 0.68115811 | Z33: 1.2654043 | AA33: 0.047361201 | AB33: 0.64879713 | AC33: 1.0377463 | AD33: 1.6863051 | AE33: 3.0492382 | AF33: 1.212276 | AG33: 2.0125687 | AH33: 1.5965385 | AI33: 2.9168145 | AJ33: 7.804062 | AK33: 1.8482251 | AL33: 3.1996793 | AM33: 2.7875311 | AN33: 3.7158508 | AO33: 11.659361 | AP33: 1.2683022 | AQ33: 4.9046141 | AR33: 6.1965904 | AS33: 5.0670986 | AT33: 17.829649 | AU33: 4.8900846 | AV33: 8.4843377 | AW33: 7.0315687 | AX33: 5.6632401 | AY33: 26.12108 | AZ33: 6.6260853 | BA33: 6.1160517 | BB33: 4.2551045 | BC33: 2.8824524 | BD33: 20.062481 | BE33: 2.212408 | BF33: 3.9266444 | BG33: -0.42451519 | BH33: 0.72285549 | BI33: 6.8696863 | BJ33: -0.26183576 | BK33: 3.5653928 | BL33: 2.6272311 | BM33: 2.0429248 | BN33: 7.9952171 | BO33: 1.6813606 | BP33: 4.9503245 | BQ33: 3.5729358 | BR33: 3.2976647 | BS33: 13.502459 | BT33: 16.779161 | BU33: 19.824705 | BV33: 22.802822
A34: Consensus Estimates - Adjusted Earnings Per Share - WAD | BJ34: N/A | BK34: N/A | BL34: N/A | BM34: N/A | BN34: N/A | BO34: N/A | BP34: N/A | BQ34: N/A | BR34: N/A | BS34: N/A | BT34: N/A | BU34: N/A | BV34: N/A
A35: Y/Y Adjusted diluted EPS growth, % | K35: 0.68220814 | L35: 2.1692512 | M35: 0.3802407 | N35: 0.54571323 | O35: 0.22898655 | P35: 0.38011109 | Q35: 0.33749469 | R35: 0.27027139 | S35: 0.33427519 | T35: -0.04144761 | U35: 0.15107479 | V35: -1.2170106 | W35: -0.48552402 | X35: -0.70037501 | Y35: -0.30141969 | Z35: -0.5341056 | AA35: 1.9304454 | AB35: 0.4789044 | AC35: 4.2963303 | AD35: 1.4756442 | AE35: 1.4096948 | AF35: 24.596395 | AG35: 2.102 | AH35: 0.53846707 | AI35: 0.72970746 | AJ35: 1.5593481 | AK35: 0.524591 | AL35: 0.58984852 | AM35: 0.74598419 | AN35: 0.27394141 | AO35: 0.49401179 | AP35: -0.31377286 | AQ35: 0.53284552 | AR35: 1.2229673 | AS35: 0.36364425 | AT35: 0.52921329 | AU35: 2.8556147 | AV35: 0.72986854 | AW35: 0.13474803 | AX35: 0.11764949 | AY35: 0.46503612 | AZ35: 0.35500422 | BA35: -0.27913623 | BB35: -0.39485701 | BC35: -0.49102416 | BD35: -0.2319429 | BE35: -0.66610632 | BF35: -0.35797724 | BG35: -1.0997661 | BH35: -0.74922205 | BI35: -0.65758541 | BJ35: -1.1183488 | BK35: -0.092000074 | BL35: 7.18878 | BM35: 1.8261871 | BN35: 0.1638402 | BO35: 7.4214322 | BP35: 0.38843736 | BQ35: 0.3599625 | BR35: 0.61418799 | BS35: 0.68881709 | BT35: 0.24267441 | BU35: 0.18150753 | BV35: 0.15022254
A37: Segmented Results - RH Segment
A38: Segmented Results - RH Segment Revenue Forecasting (FS)
A39: Design Galleries - BoP, # of stores | G39: 3 | H39: 5 | I39: 5 | J39: 5 | K39: 3 | L39: 5 | M39: 5 | N39: 6 | O39: 6 | P39: 5 | Q39: 7 | R39: 7 | S39: 7 | T39: 9 | U39: 7 | V39: 10 | W39: 10 | X39: 10 | Y39: 13 | Z39: 10 | AA39: 14 | AB39: 14 | AC39: 14 | AD39: 15 | AE39: 14 | AF39: 16 | AG39: 17 | AH39: 18 | AI39: 20 | AJ39: 16 | AK39: 20 | AL39: 20 | AM39: 20 | AN39: 21 | AO39: 20 | AP39: 22 | AQ39: 22 | AR39: 24 | AS39: 24 | AT39: 22 | AU39: 24 | AV39: 24 | AW39: 25 | AX39: 26 | AY39: 24 | AZ39: 27 | BA39: 27 | BB39: 28 | BC39: 28 | BD39: 27 | BE39: 28 | BF39: 27 | BG39: 28 | BH39: 28 | BI39: 28 | BJ39: 31 | BK39: 33 | BL39: 35 | BM39: 37 | BN39: 31 | BO39: 38 | BP39: 39 | BQ39: 40 | BR39: 41 | BS39: 38 | BT39: 41 | BU39: 42 | BV39: 42
A40: England Design Galleries opened, # of stores | O40: 0 | T40: 0 | Y40: 0 | AD40: 0 | AI40: 0 | AN40: 0 | AS40: 0 | AX40: 0 | BC40: 0 | BF40: 1 | BH40: 0 | BI40: 1
A41: Munich Design Galleries opened, # of stores | O41: 0 | T41: 0 | Y41: 0 | AD41: 0 | AI41: 0 | AN41: 0 | AS41: 0 | AX41: 0 | BC41: 0 | BH41: 1 | BI41: 1
A42: Düsseldorf Design Galleries opened, # of stores | O42: 0 | T42: 0 | Y42: 0 | AD42: 0 | AI42: 0 | AN42: 0 | AS42: 0 | AX42: 0 | BC42: 0 | BH42: 1 | BI42: 1
A43: Indianapolis Design Galleries opened, # of stores | O43: 0 | T43: 0 | Y43: 0 | AD43: 0 | AI43: 0 | AN43: 0 | AS43: 0 | AX43: 0 | BC43: 0 | BH43: 1 | BI43: 1
A44: San Francisco Design Galleries opened, # of stores | O44: 0 | T44: 0 | Y44: 0 | AD44: 0 | AI44: 0 | AN44: 0 | AS44: 0 | AX44: 0 | BA44: 1 | BC44: 0 | BD44: 1 | BH44: 0
A45: Dallas Design Galleries opened, # of stores | O45: 0 | T45: 0 | Y45: 0 | AD45: 0 | AI45: 0 | AN45: 0 | AS45: 0 | AV45: 1 | AX45: 0 | AY45: 1 | BC45: 0 | BH45: 0
...

Sheet WSM
A1: Williams Sonoma Inc.
A2: =CHOOSE(MO.DataSourceIndex,MO.Ticker.Bloomberg,MO.Ticker.CapIQ,MO.Ticker.FactSet,MO.Ticker.Thomson) -> WSM US | C2: 39845
A3: =HP.TradeCurrency -> USD | B3: =IF(MO.RealTime="OFF",MO.LastPriceHardcoded,MO.LastPriceFormula) -> 292.52 | C3: =C4-C2 -> 364 | D3: =D4-C4 -> 364 | E3: =E4-D4 -> 364 | F3: =F4-E4 -> 371 | G3: =G4-F4 -> 91 | H3: =H4-G4 -> 91 | I3: =I4-H4 -> 91 | J3: =J4-I4 -> 91 | K3: =K4-F4 -> 364 | L3: =L4-K4 -> 91 | M3: =M4-L4 -> 91 | N3: =N4-M4 -> 91 | O3: =O4-N4 -> 91 | P3: =P4-K4 -> 364 | Q3: =Q4-P4 -> 91 | R3: =R4-Q4 -> 91 | S3: =S4-R4 -> 91 | T3: =T4-S4 -> 91 | U3: =U4-P4 -> 364 | V3: =V4-U4 -> 91 | W3: =W4-V4 -> 91 | X3: =X4-W4 -> 91 | Y3: =Y4-X4 -> 91 | Z3: =Z4-U4 -> 364 | AA3: =AA4-Z4 -> 91 | AB3: =AB4-AA4 -> 91 | AC3: =AC4-AB4 -> 91 | AD3: =AD4-AC4 -> 91 | AE3: =AE4-Z4 -> 364 | AF3: =AF4-AE4 -> 91 | AG3: =AG4-AF4 -> 91 | AH3: =AH4-AG4 -> 91 | AI3: =AI4-AH4 -> 98 | AJ3: =AJ4-AE4 -> 371 | AK3: =AK4-AJ4 -> 91 | AL3: =AL4-AK4 -> 91 | AM3: =AM4-AL4 -> 91 | AN3: =AN4-AM4 -> 91 | AO3: =AO4-AJ4 -> 364 | AP3: =AP4-AO4 -> 91 | AQ3: =AQ4-AP4 -> 91 | AR3: =AR4-AQ4 -> 91 | AS3: =AS4-AR4 -> 91 | AT3: =AT4-AO4 -> 364 | AU3: =AU4-AT4 -> 91 | AV3: =AV4-AU4 -> 91 | AW3: =AW4-AV4 -> 91 | AX3: =AX4-AW4 -> 91 | AY3: =AY4-AT4 -> 364 | AZ3: =AZ4-AY4 -> 91 | BA3: =BA4-AZ4 -> 91 | BB3: =BB4-BA4 -> 91 | BC3: =BC4-BB4 -> 91 | BD3: =BD4-AY4 -> 364 | BE3: =BE4-BD4 -> 91 | BF3: =BF4-BE4 -> 91 | BG3: =BG4-BF4 -> 91 | BH3: =BH4-BG4 -> 91 | BI3: =BI4-BD4 -> 364 | BJ3: =BJ4-BI4 -> 91 | BK3: 91 | BL3: 91 | BM3: 98 | BN3: =BN4-BI4 -> 371 | BO3: 91 | BP3: 91 | BQ3: 91 | BR3: 91 | BS3: =BS4-BN4 -> 364 | BT3: 364 | BU3: 364 | BV3: 364
A4: =FP.DataSourceName -> Bloomberg | B4: =IF(AND(MO.RealTimeStockPriceToggle,MO.LastPriceFormula<>"N/A"),"ON","OFF") -> OFF | C4: 40209 | D4: 40573 | E4: 40937 | F4: 41308 | G4: 41399 | H4: 41490 | I4: 41581 | J4: =K4 -> 41672 | K4: 41672 | L4: 41763 | M4: 41854 | N4: 41945 | O4: =P4 -> 42036 | P4: 42036 | Q4: 42127 | R4: 42218 | S4: 42309 | T4: =U4 -> 42400 | U4: 42400 | V4: 42491 | W4: 42582 | X4: 42673 | Y4: =Z4 -> 42764 | Z4: 42764 | AA4: 42855 | AB4: 42946 | AC4: 43037 | AD4: =AE4 -> 43128 | AE4: 43128 | AF4: 43219 | AG4: 43310 | AH4: 43401 | AI4: =AJ4 -> 43499 | AJ4: 43499 | AK4: 43590 | AL4: 43681 | AM4: 43772 | AN4: =AO4 -> 43863 | AO4: 43863 | AP4: 43954 | AQ4: 44045 | AR4: 44136 | AS4: =AT4 -> 44227 | AT4: 44227 | AU4: 44318 | AV4: 44409 | AW4: 44500 | AX4: =AY4 -> 44591 | AY4: 44591 | AZ4: 44682 | BA4: 44773 | BB4: 44864 | BC4: =BD4 -> 44955 | BD4: 44955 | BE4: 45046 | BF4: 45137 | BG4: 45228 | BH4: =BI4 -> 45319 | BI4: 45319 | BJ4: 45410 | BK4: =BJ4+BK3 -> 45501 | BL4: =BK4+BL3 -> 45592 | BM4: =BL4+BM3 -> 45690 | BN4: =BM4 -> 45690 | BO4: =BN4+BO3 -> 45781 | BP4: =BO4+BP3 -> 45872 | BQ4: =BP4+BQ3 -> 45963 | BR4: =BQ4+BR3 -> 46054 | BS4: =BR4 -> 46054 | BT4: =BS4+BT3 -> 46418 | BU4: =BT4+BU3 -> 46782 | BV4: =BU4+BV3 -> 47146
A5: =MO.ReportCurrency -> USD | C5: FY2009 | D5: =CONCATENATE("FY",RIGHT(C5,4)+1) -> FY2010 | E5: =CONCATENATE("FY",RIGHT(D5,4)+1) -> FY2011 | F5: =CONCATENATE("FY",RIGHT(E5,4)+1) -> FY2012 | G5: =CONCATENATE("Q1","-",RIGHT(F5,4)+1) -> Q1-2013 | H5: =CONCATENATE("Q2","-",RIGHT(G5,4)) -> Q2-2013 | I5: =CONCATENATE("Q3","-",RIGHT(H5,4)) -> Q3-2013 | J5: =CONCATENATE("Q4","-",RIGHT(I5,4)) -> Q4-2013 | K5: =CONCATENATE("FY",RIGHT(F5,4)+1) -> FY2013 | L5: =CONCATENATE("Q1","-",RIGHT(K5,4)+1) -> Q1-2014 | M5: =CONCATENATE("Q2","-",RIGHT(L5,4)) -> Q2-2014 | N5: =CONCATENATE("Q3","-",RIGHT(M5,4)) -> Q3-2014 | O5: =CONCATENATE("Q4","-",RIGHT(N5,4)) -> Q4-2014 | P5: =CONCATENATE("FY",RIGHT(K5,4)+1) -> FY2014 | Q5: =CONCATENATE("Q1","-",RIGHT(P5,4)+1) -> Q1-2015 | R5: =CONCATENATE("Q2","-",RIGHT(Q5,4)) -> Q2-2015 | S5: =CONCATENATE("Q3","-",RIGHT(R5,4)) -> Q3-2015 | T5: =CONCATENATE("Q4","-",RIGHT(S5,4)) -> Q4-2015 | U5: =CONCATENATE("FY",RIGHT(P5,4)+1) -> FY2015 | V5: =CONCATENATE("Q1","-",RIGHT(U5,4)+1) -> Q1-2016 | W5: =CONCATENATE("Q2","-",RIGHT(V5,4)) -> Q2-2016 | X5: =CONCATENATE("Q3","-",RIGHT(W5,4)) -> Q3-2016 | Y5: =CONCATENATE("Q4","-",RIGHT(X5,4)) -> Q4-2016 | Z5: =CONCATENATE("FY",RIGHT(U5,4)+1) -> FY2016 | AA5: =CONCATENATE("Q1","-",RIGHT(Z5,4)+1) -> Q1-2017 | AB5: =CONCATENATE("Q2","-",RIGHT(AA5,4)) -> Q2-2017 | AC5: =CONCATENATE("Q3","-",RIGHT(AB5,4)) -> Q3-2017 | AD5: =CONCATENATE("Q4","-",RIGHT(AC5,4)) -> Q4-2017 | AE5: =CONCATENATE("FY",RIGHT(Z5,4)+1) -> FY2017 | AF5: =CONCATENATE("Q1","-",RIGHT(AE5,4)+1) -> Q1-2018 | AG5: =CONCATENATE("Q2","-",RIGHT(AF5,4)) -> Q2-2018 | AH5: =CONCATENATE("Q3","-",RIGHT(AG5,4)) -> Q3-2018 | AI5: =CONCATENATE("Q4","-",RIGHT(AH5,4)) -> Q4-2018 | AJ5: =CONCATENATE("FY",RIGHT(AE5,4)+1) -> FY2018 | AK5: =CONCATENATE("Q1","-",RIGHT(AJ5,4)+1) -> Q1-2019 | AL5: =CONCATENATE("Q2","-",RIGHT(AK5,4)) -> Q2-2019 | AM5: =CONCATENATE("Q3","-",RIGHT(AL5,4)) -> Q3-2019 | AN5: =CONCATENATE("Q4","-",RIGHT(AM5,4)) -> Q4-2019 | AO5: =CONCATENATE("FY",RIGHT(AJ5,4)+1) -> FY2019 | AP5: =CONCATENATE("Q1","-",RIGHT(AO5,4)+1) -> Q1-2020 | AQ5: =CONCATENATE("Q2","-",RIGHT(AP5,4)) -> Q2-2020 | AR5: =CONCATENATE("Q3","-",RIGHT(AQ5,4)) -> Q3-2020 | AS5: =CONCATENATE("Q4","-",RIGHT(AR5,4)) -> Q4-2020 | AT5: =CONCATENATE("FY",RIGHT(AO5,4)+1) -> FY2020 | AU5: =CONCATENATE("Q1","-",RIGHT(AT5,4)+1) -> Q1-2021 | AV5: =CONCATENATE("Q2","-",RIGHT(AU5,4)) -> Q2-2021 | AW5: =CONCATENATE("Q3","-",RIGHT(AV5,4)) -> Q3-2021 | AX5: =CONCATENATE("Q4","-",RIGHT(AW5,4)) -> Q4-2021 | AY5: =CONCATENATE("FY",RIGHT(AT5,4)+1) -> FY2021 | AZ5: =CONCATENATE("Q1","-",RIGHT(AY5,4)+1) -> Q1-2022 | BA5: =CONCATENATE("Q2","-",RIGHT(AZ5,4)) -> Q2-2022 | BB5: =CONCATENATE("Q3","-",RIGHT(BA5,4)) -> Q3-2022 | BC5: =CONCATENATE("Q4","-",RIGHT(BB5,4)) -> Q4-2022 | BD5: =CONCATENATE("FY",RIGHT(AY5,4)+1) -> FY2022 | BE5: =CONCATENATE("Q1","-",RIGHT(BD5,4)+1) -> Q1-2023 | BF5: =CONCATENATE("Q2","-",RIGHT(BE5,4)) -> Q2-2023 | BG5: =CONCATENATE("Q3","-",RIGHT(BF5,4)) -> Q3-2023 | BH5: =CONCATENATE("Q4","-",RIGHT(BG5,4)) -> Q4-2023 | BI5: =CONCATENATE("FY",RIGHT(BD5,4)+1) -> FY2023 | BJ5: =CONCATENATE("Q1","-",RIGHT(BI5,4)+1) -> Q1-2024 | BK5: =CONCATENATE("Q2","-",RIGHT(BJ5,4)) -> Q2-2024 | BL5: =CONCATENATE("Q3","-",RIGHT(BK5,4)) -> Q3-2024 | BM5: =CONCATENATE("Q4","-",RIGHT(BL5,4)) -> Q4-2024 | BN5: =CONCATENATE("FY",RIGHT(BI5,4)+1) -> FY2024 | BO5: =CONCATENATE("Q1","-",RIGHT(BN5,4)+1) -> Q1-2025 | BP5: =CONCATENATE("Q2","-",RIGHT(BO5,4)) -> Q2-2025 | BQ5: =CONCATENATE("Q3","-",RIGHT(BP5,4)) -> Q3-2025 | BR5: =CONCATENATE("Q4","-",RIGHT(BQ5,4)) -> Q4-2025 | BS5: =CONCATENATE("FY",RIGHT(BN5,4)+1) -> FY2025 | BT5: =CONCATENATE("FY",RIGHT(BS5,4)+1) -> FY2026 | BU5: =CONCATENATE("FY",RIGHT(BT5,4)+1) -> FY2027 | BV5: =CONCATENATE("FY",RIGHT(BU5,4)+1) -> FY2028
A6: Consolidated Summary
A7: Total Company Operated Stores - EoP, # of stores | C7: =C272 -> 610 | D7: =D272 -> 592 | E7: =E272 -> 576 | F7: =F272 -> 581 | G7: =G272 -> 587 | H7: =H272 -> 590 | I7: =I272 -> 595 | J7: =J272 -> 585 | ... BV7: =BV272 -> 459
A8: Q/Q Total company operated store growth, % | G8: =G7/F7-1 -> 0.010327022 | H8: =H7/G7-1 -> 0.0051107325 | I8: =I7/H7-1 -> 0.0084745763 | J8: =J7/I7-1 -> -0.016806723 | L8: =L7/J7-1 -> 0.0068376068 | M8: =M7/L7-1 -> 0 | N8: =N7/M7-1 -> 0.0237691 | O8: =O7/N7-1 -> -0.0033167496 | Q8: =Q7/O7-1 -> 0.003327787 | R8: =R7/Q7-1 -> 0.014925373 | S8: =S7/R7-1 -> 0.017973856 | T8: =T7/S7-1 -> -0.0080256822 | V8: =V7/T7-1 -> 0.0097087379 | W8: =W7/V7-1 -> 0.0032051282 | X8: =X7/W7-1 -> 0.014376997 | Y8: =Y7/X7-1 -> -0.0094488189 | AA8: =AA7/Y7-1 -> -0.0015898251 | AB8: =AB7/AA7-1 -> 0.011146497 | AC8: =AC7/AB7-1 -> 0.0015748031 | AD8: =AD7/AC7-1 -> -0.0078616352 | AF8: =AF7/AD7-1 -> -0.0063391442 | AG8: =AG7/AF7-1 -> 0.0079744817 | AH8: =AH7/AG7-1 -> 0.0015822785 | AI8: =AI7/AH7-1 -> -0.012638231 | AK8: =AK7/AI7-1 -> 0 | AL8: =AL7/AK7-1 -> -0.0032 | AM8: =AM7/AL7-1 -> 0.0048154093 | AN8: =AN7/AM7-1 -> -0.019169329 | AP8: =AP7/AN7-1 -> 0.003257329 | AQ8: =AQ7/AP7-1 -> -0.0032467532 | AR8: =AR7/AQ7-1 -> 0 | AS8: =AS7/AR7-1 -> -0.053745928 | AU8: =AU7/AS7-1 -> -0.0051635112 | AV8: =AV7/AU7-1 -> 0.0051903114 | AW8: =AW7/AV7-1 -> -0.0068846816 | AX8: =AX7/AW7-1 -> -0.057192374 | AZ8: =AZ7/AX7-1 -> 0.0018382353 | BA8: =BA7/AZ7-1 -> 0.0018348624 | BB8: =BB7/BA7-1 -> 0.0018315018 | BC8: =BC7/BB7-1 -> -0.031078611 | BE8: =BE7/BC7-1 -> 0.0018867925 | BF8: =BF7/BE7-1 -> 0.0018832392 | BG8: =BG7/BF7-1 -> 0.0018796992 | BH8: =BH7/BG7-1 -> -0.028142589 | BJ8: =BJ7/BH7-1 -> -0.0019305019 | BK8: =BK7/BJ7-1 -> -0.0077369439 | BL8: =BL7/BK7-1 -> -0.007797271 | BM8: =BM7/BL7-1 -> -0.0078585462 | BO8: =BO7/BM7-1 -> -0.0079207921 | BP8: =BP7/BO7-1 -> -0.0079840319 | BQ8: =BQ7/BP7-1 -> -0.0080482897 | BR8: =BR7/BQ7-1 -> -0.0081135903
A9: Y/Y Total company operated store growth, % | D9: =D7/C7-1 -> -0.029508197 | E9: =E7/D7-1 -> -0.027027027 | F9: =F7/E7-1 -> 0.0086805556 | K9: =K7/F7-1 -> 0.0068846816 | L9: =L7/G7-1 -> 0.003407155 | M9: =M7/H7-1 -> -0.0016949153 | N9: =N7/I7-1 -> 0.013445378 | O9: =O7/J7-1 -> 0.027350427 | P9: =P7/K7-1 -> 0.027350427 | Q9: =Q7/L7-1 -> 0.0237691 | R9: =R7/M7-1 -> 0.039049236 | ... BS9: =BS7/BN7-1 -> -0.031683168 | BT9: =BT7/BS7-1 -> -0.020449898 | BU9: =BU7/BT7-1 -> -0.020876827 | BV9: =BV7/BU7-1 -> -0.021321962
A11: Pottery Barn Revenue, mm | C11: =C284 -> 1304.319 | D11: =D284 -> 1511.029 | E11: =E284 -> 1600.847 | F11: =F284 -> 1752.997 | K11: =K284 -> 1910.978 | P11: =P284 -> 2022.331 | U11: =U284 -> 2074.051 | Z11: =Z284 -> 2024.218 | AE11: =AE284 -> 2066.302 | AF11: =AF284 -> 490.372 | AG11: =AG284 -> 506.46 | AH11: =AH284 -> 533.469 | AI11: =AI284 -> 647.043 | AJ11: =AJ284 -> 2177.344 | AK11: =AK284 -> 492.126 | AL11: =AL284 -> 524.847 | ... BV11: =BV284 -> 4050.6768
A12: Y/Y Pottery Barn comparable brand revenue growth, % | C12: =C274 -> -0.111 | D12: =D274 -> 0.177 | E12: =E274 -> 0.076 | F12: =F274 -> 0.085 | G12: =G274 -> 0.076 | H12: =H274 -> 0.099 | I12: =I274 -> 0.084 | J12: =J274 -> 0.146 | ... BV12: =BV274 -> 0.09
A13: Y/Y Pottery Barn revenue growth, % | D13: =D11/C11-1 -> 0.15848117 | E13: =E11/D11-1 -> 0.059441612 | F13: =F11/E11-1 -> 0.095043436 | K13: =K11/F11-1 -> 0.090120519 | P13: =P11/K11-1 -> 0.058270163 | U13: =U11/P11-1 -> 0.025574448 | Z13: =Z11/U11-1 -> -0.024026892 | AE13: =AE11/Z11-1 -> 0.020790251 | AJ13: =AJ11/AE11-1 -> 0.053739482 | AK13: =AK11/AF11-1 -> 0.0035768763 | AL13: =AL11/AG11-1 -> 0.03630494 | AM13: =AM11/AH11-1 -> 0.044081287 | AN13: =AN11/AI11-1 -> -0.010206431 | AO13: =AO11/AJ11-1 -> 0.017017522 | AP13: =AP11/AK11-1 -> -0.025422351 | AQ13: =AQ11/AL11-1 -> 0.073219433 | ... BS13: =BS11/BN11-1 -> 0.014895422 | BT13: =BT11/BS11-1 -> 0.064953002 | BU13: =BU11/BT11-1 -> 0.09 | BV13: =BV11/BU11-1 -> 0.09
A15: West Elm Revenue, mm | C15: =C285 -> 211.576 | D15: =D285 -> 259.936 | E15: =E285 -> 335.98 | F15: =F285 -> 430.099 | K15: =K285 -> 531.305 | P15: =P285 -> 669.074 | U15: =U285 -> 821.136 | Z15: =Z285 -> 971.568 | AE15: =AE285 -> 1114.339 | AF15: =AF285 -> 273.349 | AG15: =AG285 -> 301.213 | AH15: =AH285 -> 339.099 | AI15: =AI285 -> 379.267 | AJ15: =AJ285 -> 1292.928 | AK15: =AK285 -> 309.483 | AL15: =AL285 -> 357.574 | ... BV15: =BV285 -> 2257.3246
A16: Y/Y West Elm comparable brand revenue growth, % | C16: =C275 -> -0.12 | D16: =D275 -> 0.164 | E16: =E275 -> 0.303 | F16: =F275 -> 0.174 | G16: =G275 -> 0.118 | H16: =H275 -> 0.165 | I16: =I275 -> 0.222 | J16: =J275 -> 0.183 | ... BV16: =BV275 -> 0.08
A17: Y/Y West Elm revenue growth, % | D17: =D15/C15-1 -> 0.22857035 | E17: =E15/D15-1 -> 0.29254894 | F17: =F15/E15-1 -> 0.28013275 | K17: =K15/F15-1 -> 0.23530861 | P17: =P15/K15-1 -> 0.25930304 | U17: =U15/P15-1 -> 0.22727232 | Z17: =Z15/U15-1 -> 0.18319986 | AE17: =AE15/Z15-1 -> 0.14694906 | AJ17: =AJ15/AE15-1 -> 0.16026452 | AK17: =AK15/AF15-1 -> 0.13218998 | AL17: =AL15/AG15-1 -> 0.18711344 | AM17: =AM15/AH15-1 -> 0.15111221 | AN17: =AN15/AI15-1 -> 0.078762455 | AO17: =AO15/AJ15-1 -> 0.13427585 | AP17: =AP15/AK15-1 -> 0.019215918 | AQ17: =AQ15/AL15-1 -> 0.064260824 | ... BS17: =BS15/BN15-1 -> 0.027787727 | BT17: =BT15/BS15-1 -> 0.075139028 | BU17: =BU15/BT15-1 -> 0.056853388 | BV17: =BV15/BU15-1 -> 0.055998153
A19: Williams Sonoma Revenue, mm | C19: =C286 -> 958.461 | D19: =D286 -> 1006.086 | E19: =E286 -> 994.425 | F19: =F286 -> 980.709 | K19: =K286 -> 978.002 | P19: =P286 -> 994.651 | U19: =U286 -> 993.609 | Z19: =Z286 -> 1002.194 | AE19: =AE286 -> 1022.434 | AF19: =AF286 -> 200.977 | AG19: =AG286 -> 195.178 | AH19: =AH286 -> 203.936 | AI19: =AI286 -> 456.034 | AJ19: =AJ286 -> 1056.125 | AK19: =AK286 -> 194.894 | AL19: =AL286 -> 191.374 | ... BV19: =BV286 -> 1648.7005
A20: Y/Y Williams Sonoma comparable brand revenue growth, % | C20: =C276 -> -0.032 | D20: =D276 -> 0.05 | E20: =E276 -> -0.003 | F20: =F276 -> -0.011 | G20: =G276 -> 0.019 | H20: =H276 -> -0.004 | I20: =I276 -> 0.014 | J20: =J276 -> 0.023 | ... BV20: =BV276 -> 0.08
A21: Y/Y Williams Sonoma revenue growth, % | D21: =D19/C19-1 -> 0.049689033 | E21: =E19/D19-1 -> -0.01159046 | F21: =F19/E19-1 -> -0.013792895 | K21: =K19/F19-1 -> -0.0027602479 | P21: =P19/K19-1 -> 0.017023483 | U21: =U19/P19-1 -> -0.0010476036 | Z21: =Z19/U19-1 -> 0.0086402196 | AE21: =AE19/Z19-1 -> 0.020195691 | AJ21: =AJ19/AE19-1 -> 0.03295176 | AK21: =AK19/AF19-1 -> -0.030267145 | AL21: =AL19/AG19-1 -> -0.019489902 | AM21: =AM19/AH19-1 -> 0.0076347482 | AN21: =AN19/AI19-1 -> -0.033828618 | AO21: =AO19/AJ19-1 -> -0.022494496 | AP21: =AP19/AK19-1 -> 0.022617423 | AQ21: =AQ19/AL19-1 -> 0.27045994 | ... BS21: =BS19/BN19-1 -> 0.015817189 | BT21: =BT19/BS19-1 -> 0.074623893 | BU21: =BU19/BT19-1 -> 0.082328805 | BV21: =BV19/BU19-1 -> 0.082371209
A23: Pottery Barn Kids and Teen Revenue, mm | C23: =C289 -> 596.239 | D23: =D289 -> 685.282 | E23: =E289 -> 733.835 | F23: =F289 -> 777.597 | K23: =K289 -> 844.077 | P23: =P289 -> 885.211 | U23: =U289 -> 893.675 | Z23: =Z289 -> 873.199 | AE23: =AE289 -> 860.468 | AF23: =AF289 -> 180.396 | AG23: =AG289 -> 213.807 | AH23: =AH289 -> 227.331 | AI23: =AI289 -> 274.228 | AJ23: =AJ289 -> 895.762 | AK23: =AK289 -> 177.046 | AL23: =AL289 -> 227.853 | ... BV23: =BV289 -> 1246.7476
A24: Y/Y Pottery Barn Kids and Teen comparable brand revenue growth, % | AG24: =AG279 -> 0.057 | AH24: =AH279 -> 0 | AI24: =AI279 -> 0.016 | AJ24: =AJ279 -> 0.028 | AK24: =AK279 -> 0.012 | AL24: =AL279 -> 0.037 | AM24: =AM279 -> 0.04 | AN24: =AN279 -> 0.079 | ... BV24: =BV279 -> 0.05
A25: Y/Y Pottery Barn Kids and Teen revenue growth, % | D25: =D23/C23-1 -> 0.14934112 | E25: =E23/D23-1 -> 0.070851124 | F25: =F23/E23-1 -> 0.059634659 | K25: =K23/F23-1 -> 0.085494157 | P25: =P23/K23-1 -> 0.048732521 | U25: =U23/P23-1 -> 0.0095615622 | Z25: =Z23/U23-1 -> -0.022912132 | AE25: =AE23/Z23-1 -> -0.014579724 | AJ25: =AJ23/AE23-1 -> 0.041017214 | AK25: =AK23/AF23-1 -> -0.018570257 | AL25: =AL23/AG23-1 -> 0.065694762 | AM25: =AM23/AH23-1 -> 0.0031671879 | AN25: =AN23/AI23-1 -> 0.0050432487 | AO25: =AO23/AJ23-1 -> 0.014288394 | AP25: =AP23/AK23-1 -> 0.06498876 | AQ25: =AQ23/AL23-1 -> 0.035698455 | ... BS25: =BS23/BN23-1 -> 0.05218104 | BT25: =BT23/BS23-1 -> 0.04 | BU25: =BU23/BT23-1 -> 0.04 | BV25: =BV23/BU23-1 -> 0.04
A27: Other Revenue, mm | C27: =C290 -> 32.109 | D27: =D290 -> 41.825 | E27: =E290 -> 55.808 | F27: =F290 -> 101.468 | K27: =K290 -> 123.527 | P27: =P290 -> 127.452 | U27: =U290 -> 193.619 | Z27: =Z290 -> 212.633 | AE27: =AE290 -> 228.816 | AF27: =AF290 -> 57.906 | AG27: =AG290 -> 58.516 | AH27: =AH290 -> 53.148 | AI27: =AI290 -> 79.864 | AJ27: =AJ290 -> 249.434 | AK27: =AK290 -> 67.583 | AL27: =AL290 -> 69.166 | ... BV27: =BV290 -> 482.06109
A28: Y/Y Other revenue growth, % | D28: =D27/C27-1 -> 0.30259429 | E28: =E27/D27-1 -> 0.33432158 | F28: =F27/E27-1 -> 0.81816227 | K28: =K27/F27-1 -> 0.21739859 | P28: =P27/K27-1 -> 0.03177443 | U28: =U27/P27-1 -> 0.51915231 | Z28: =Z27/U27-1 -> 0.098203172 | AE28: =AE27/Z27-1 -> 0.07610766 | AJ28: =AJ27/AE27-1 -> 0.090107335 | AK28: =AK27/AF27-1 -> 0.16711567 | AL28: =AL27/AG27-1 -> 0.1820015 | AM28: =AM27/AH27-1 -> 0.15906525 | AN28: =AN27/AI27-1 -> -0.025919062 | AO28: =AO27/AJ27-1 -> 0.10708644 | AP28: =AP27/AK27-1 -> -0.22607756 | AQ28: =AQ27/AL27-1 -> -0.019330307 | ... BS28: =BS27/BN27-1 -> 0.05 | BT28: =BT27/BS27-1 -> 0.05 | BU28: =BU27/BT27-1 -> 0.05 | BV28: =BV27/BU27-1 -> 0.05
A30: Total Revenue, mm | C30: =C749 -> 3102.704 | D30: =D749 -> 3504.158 | E30: =E749 -> 3720.895 | F30: =F749 -> 4042.87 | G30: =G749 -> 887.808 | H30: =H749 -> 982.209 | I30: =I749 -> 1051.548 | J30: =J749 -> 1466.324 | ... BV30: =BV749 -> 9685.5106
A31: =A752 -> Consensus Estimates - Net Revenue | BK31: =BK752 -> N/A | BL31: =BL752 -> N/A | BM31: =BM752 -> N/A | BN31: =BN752 -> N/A | BO31: =BO752 -> N/A | BP31: =BP752 -> N/A | BQ31: =BQ752 -> N/A | BR31: =BR752 -> N/A | ... BV31: =BV752 -> N/A
A32: Y/Y Comparable demand growth, % | AH32: =AH282 -> 0.046 | AQ32: =AQ282 -> 0.19 | AR32: =AR282 -> 0.31 | AS32: =AS282 -> 0.3 | AU32: =AU282 -> 0.4 | AW32: =AW282 -> 0.169 | AX32: =AX282 -> 0.108 | AZ32: =AZ282 -> 0.095 | BC32: =BC282 -> -0.05 | BE32: =BE282 -> -0.1 | BF32: =BF282 -> -0.114 | BG32: =BG282 -> -0.118
A33: Y/Y Comparable brand revenue growth, % | C33: =C280 -> -0.093 | D33: =D280 -> 0.139 | E33: =E280 -> 0.073 | F33: =F280 -> 0.061 | G33: =G280 -> 0.072 | H33: =H280 -> 0.084 | I33: =I280 -> 0.082 | J33: =J280 -> 0.104 | ... BV33: =BV280 -> 0.080139729
A34: Y/Y Total revenue growth, % | D34: =D30/C30-1 -> 0.12938843 | E34: =E30/D30-1 -> 0.061851378 | F34: =F30/E30-1 -> 0.086531601 | K34: =K30/F30-1 -> 0.085340117 | L34: =L30/G30-1 -> 0.097455756 | M34: =M30/H30-1 -> 0.057923517 | N34: =N30/I30-1 -> 0.087122984 | O34: =O30/J30-1 -> 0.051694578 | P34: =P30/K30-1 -> 0.070838164 | Q34: =Q30/L30-1 -> 0.057830509 | R34: =R30/M30-1 -> 0.084617295 | ... BS34: =BS30/BN30-1 -> 0.024991776 | BT34: =BT30/BS30-1 -> 0.064693372 | BU34: =BU30/BT30-1 -> 0.07185334 | BV34: =BV30/BU30-1 -> 0.072002431
A36: E-Commerce net revenue as % of total net revenue, % | C36: =C397 -> 0.39471055 | D36: =D397 -> 0.41452811 | E36: =E397 -> 0.43882211 | F36: =F397 -> 0.46239083 | G36: =G397 -> 0.4720435 | H36: =H397 -> 0.48630892 | I36: =I397 -> 0.48678139 | J36: =J397 -> 0.48175369 | ... AJ36: =AJ397 -> 0.54342122 | AL36: =AL397 -> 0.56610226 | AO36: =AO397 -> 0.562 | AP36: =AP397 -> 0.62758549 | AQ36: =AQ397 -> 0.76 | AR36: =AR397 -> 0.7 | AS36: =AS397 -> 0.7 | AT36: =AT397 -> 0.7 | AU36: =AU397 -> 0.65 | AV36: =AV397 -> 0.65 | ... BD36: =BD397 -> 0.66 | BF36: =BF397 -> 0.66 | BI36: =BI397 -> 0.66
A37: Y/Y E-Commerce net revenue growth, % | D37: =D390 -> 0.18609258 | E37: =E390 -> 0.12408266 | F37: =F390 -> 0.14488817 | K37: =K390 -> 0.13139929 | L37: =L390 -> 0.17229243 | M37: =M390 -> 0.0940675 | N37: =N390 -> 0.1467197 | O37: =O390 -> 0.089796675 | P37: =P390 -> 0.12088385 | Q37: =Q390 -> 0.084032006 | R37: =R390 -> 0.090556824 | ... AJ37: =AJ390 -> 0.1092718 | AL37: =AL390 -> 0.12967456 | AO37: =AO390 -> 0.075474259 | AQ37: =AQ390 -> 0.46 | AT37: =AT390 -> 0.43248567 | AU37: =AU390 -> 0.46655764 | AV37: =AV390 -> 0.11776783 | AW37: =AW390 -> 0.11065307 | AX37: =AX390 -> 0.038823261 | AY37: =AY390 -> 0.14617765 | AZ37: =AZ390 -> 0.081301111 | BA37: =BA390 -> 0.10385876 | ... BD37: =BD390 -> 0.051962688 | BF37: =BF390 -> -0.12062238 | BI37: =BI390 -> -0.10649304
A39: Adjusted Gross Profit, mm | C39: =C323 -> 1103.237 | D39: =D323 -> 1373.859 | E39: =E323 -> 1459.856 | F39: =F323 -> 1592.476 | G39: =G323 -> 334.185 | H39: =H323 -> 368.924 | I39: =I323 -> 405.388 | J39: =J323 -> 595.719 | ... BV39: =BV323 -> 4539.0662
A40: Consensus Estimates - Adjusted Gross Profit | BK40: =IFERROR(BK626*BK752,"N/A") -> N/A | BL40: =IFERROR(BL626*BL752,"N/A") -> N/A | BM40: =IFERROR(BM626*BM752,"N/A") -> N/A | BN40: =IFERROR(BN626*BN752,"N/A") -> N/A | BO40: =IFERROR(BO626*BO752,"N/A") -> N/A | BP40: =IFERROR(BP626*BP752,"N/A") -> N/A | BQ40: =IFERROR(BQ626*BQ752,"N/A") -> N/A | BR40: =IFERROR(BR626*BR752,"N/A") -> N/A | ... BV40: =IFERROR(BV626*BV752,"N/A") -> N/A
A41: Adjusted gross margin, % | C41: =C327 -> 0.35557275 | D41: =D327 -> 0.39206537 | E41: =E327 -> 0.39234001 | F41: =F327 -> 0.3938974 | G41: =G327 -> 0.37641585 | H41: =H327 -> 0.37560641 | I41: =I327 -> 0.38551545 | J41: =J327 -> 0.40626696 | ... BV41: =BV327 -> 0.468645
A42: Y/Y Adjusted gross margin improvement, bps | D42: =(D41-C41)*10000 -> 364.92617 | E42: =(E41-D41)*10000 -> 2.7464577 | F42: =(F41-E41)*10000 -> 15.573896 | K42: =(K41-F41)*10000 -> -55.065405 | L42: =(L41-G41)*10000 -> 16.983446 | M42: =(M41-H41)*10000 -> -78.86979 | N42: =(N41-I41)*10000 -> -81.349908 | O42: =(O41-J41)*10000 -> -51.380025 | P42: =(P41-K41)*10000 -> -52.004668 | Q42: =(Q41-L41)*10000 -> -105.48632 | R42: =(R41-M41)*10000 -> -69.253816 | ... BS42: =(BS41-BN41)*10000 -> -26.232159 | BT42: =(BT41-BS41)*10000 -> 38.192089 | BU42: =(BU41-BT41)*10000 -> 43.478671 | BV42: =(BV41-BU41)*10000 -> 42.102726
